Workbook

Sheet README
A1: Metro Buddy - plan workbook
A2: Spec | B2: metro-buddy-spec.md
A3: Ontology | B3: metro-buddy-ontology.md
A5: Tabs
A6: Features | B6: Feature catalog. Task count, estimate and done count are formulas from Tasks.
A7: Tasks | B7: Build tasks in order. Edit the yellow Status / Owner columns.
A8: Phase Summary | B8: Effort and progress per phase (formulas).
A9: Entities | B9: Data model entities by domain with retention.
A10: Fields | B10: Every field: type, constraints, privacy class.
A11: Enums | B11: Enum types and allowed values.
A13: Phases | B13: P0 Foundation | P1 Bowls | P2 Chat | P3 Travel Buddy (MVP launch) | P4 Vent Studio | P5 Trust & growth | P6 Later
A14: Priority | B14: MoSCoW: Must / Should / Could
A15: Privacy class | B15: P0 system/public, P1 pseudonymous, P2 personal (owner only), P3 sensitive (hashed/encrypted)
A16: Assumption | B16: Est (days) = rough single-developer estimates made by Claude for planning only; revise with your team.

Sheet Features
A1: Feature ID | B1: Module | C1: Feature | D1: Description | E1: Phase | F1: Priority | G1: User value | H1: Depends on | I1: Tasks | J1: Est (days) | K1: Tasks done
A2: F01 | B2: Identity | C2: Phone OTP login | D2: Indian mobile number + 6-digit OTP via MSG91; JWT access + rotating refresh token in secure store | E2: P0 | F2: Must | G2: Frictionless, no password | I2: =COUNTIF(Tasks!$C$2:$C$86,A2) | J2: =SUMIF(Tasks!$C$2:$C$86,A2,Tasks!$H$2:$H$86) | K2: =COUNTIFS(Tasks!$C$2:$C$86,A2,Tasks!$J$2:$J$86,"Done")
A3: F02 | B3: Identity | C3: Anonymous persona | D3: Auto alias (e.g. 'Chai Comet 27') + generated avatar; re-roll at signup; alias change once / 30 days | E3: P0 | F3: Must | G3: Be yourself without being exposed | H3: F01 | I3: =COUNTIF(Tasks!$C$2:$C$86,A3) | J3: =SUMIF(Tasks!$C$2:$C$86,A3,Tasks!$H$2:$H$86) | K3: =COUNTIFS(Tasks!$C$2:$C$86,A3,Tasks!$J$2:$J$86,"Done")
A4: F03 | B4: Identity | C4: Vibe profile | D4: Pick 3-10 vibe tags (chatty/quiet, music, cricket, books, startup talk...) and intents (vent, listen, travel buddy, friends) | E4: P0 | F4: Must | G4: Find people like you | H4: F02 | I4: =COUNTIF(Tasks!$C$2:$C$86,A4) | J4: =SUMIF(Tasks!$C$2:$C$86,A4,Tasks!$H$2:$H$86) | K4: =COUNTIFS(Tasks!$C$2:$C$86,A4,Tasks!$J$2:$J$86,"Done")
A5: F04 | B5: Identity | C5: Home metro setup | D5: City, home station, work/college station, usual line | E5: P0 | F5: Must | G5: Personalised bowls and matches | H5: F02 | I5: =COUNTIF(Tasks!$C$2:$C$86,A5) | J5: =SUMIF(Tasks!$C$2:$C$86,A5,Tasks!$H$2:$H$86) | K5: =COUNTIFS(Tasks!$C$2:$C$86,A5,Tasks!$J$2:$J$86,"Done")
A6: F05 | B6: Identity | C6: Age gate & consents | D6: 18+ declaration, DPDP itemised consents (core, matching, AI processing, analytics), privacy policy acceptance | E6: P0 | F6: Must | G6: Trust and legal compliance | H6: F01 | I6: =COUNTIF(Tasks!$C$2:$C$86,A6) | J6: =SUMIF(Tasks!$C$2:$C$86,A6,Tasks!$H$2:$H$86) | K6: =COUNTIFS(Tasks!$C$2:$C$86,A6,Tasks!$J$2:$J$86,"Done")
A7: F06 | B7: Identity | C7: Device integrity | D7: Play Integrity / App Attest check at signup to cut bot and multi-account abuse | E7: P6 | F7: Could | G7: Fewer fake accounts | H7: F01 | I7: =COUNTIF(Tasks!$C$2:$C$86,A7) | J7: =SUMIF(Tasks!$C$2:$C$86,A7,Tasks!$H$2:$H$86) | K7: =COUNTIFS(Tasks!$C$2:$C$86,A7,Tasks!$J$2:$J$86,"Done")
A8: F07 | B8: Identity | C8: Selfie verification badge | D8: Liveness selfie via KYC vendor; only a 'verified' boolean is kept, the image is discarded | E8: P6 | F8: Could | G8: Safer travel matches | H8: F01 | I8: =COUNTIF(Tasks!$C$2:$C$86,A8) | J8: =SUMIF(Tasks!$C$2:$C$86,A8,Tasks!$H$2:$H$86) | K8: =COUNTIFS(Tasks!$C$2:$C$86,A8,Tasks!$J$2:$J$86,"Done")
A9: F08 | B9: Identity | C9: Reveal ladder | D9: Mutual, step-wise reveal per conversation: first name -> photo -> contact; revocable | E9: P5 | F9: Should | G9: Turn strangers into friends safely | H9: F20 | I9: =COUNTIF(Tasks!$C$2:$C$86,A9) | J9: =SUMIF(Tasks!$C$2:$C$86,A9,Tasks!$H$2:$H$86) | K9: =COUNTIFS(Tasks!$C$2:$C$86,A9,Tasks!$J$2:$J$86,"Done")
A10: F10 | B10: Bowls | C10: Bowl discovery & join | D10: Auto-suggested bowls by line, station, office hub, college and topic; join/leave | E10: P1 | F10: Must | G10: Find your crowd | H10: F04 | I10: =COUNTIF(Tasks!$C$2:$C$86,A10) | J10: =SUMIF(Tasks!$C$2:$C$86,A10,Tasks!$H$2:$H$86) | K10: =COUNTIFS(Tasks!$C$2:$C$86,A10,Tasks!$J$2:$J$86,"Done")
A11: F11 | B11: Bowls | C11: Posts | D11: Anonymous text/image/poll posts with flair, in a bowl | E11: P1 | F11: Must | G11: Vent and share | H11: F10,F24 | I11: =COUNTIF(Tasks!$C$2:$C$86,A11) | J11: =SUMIF(Tasks!$C$2:$C$86,A11,Tasks!$H$2:$H$86) | K11: =COUNTIFS(Tasks!$C$2:$C$86,A11,Tasks!$J$2:$J$86,"Done")
A12: F12 | B12: Bowls | C12: Comments & votes | D12: Threaded comments (2 levels), up/down votes, OP badge | E12: P1 | F12: Must | G12: Discussion | H12: F11 | I12: =COUNTIF(Tasks!$C$2:$C$86,A12) | J12: =SUMIF(Tasks!$C$2:$C$86,A12,Tasks!$H$2:$H$86) | K12: =COUNTIFS(Tasks!$C$2:$C$86,A12,Tasks!$J$2:$J$86,"Done")
A13: F13 | B13: Bowls | C13: Feed ranking | D13: Home and bowl feeds with Hot/New/Top; hot score precomputed every 5 min | E13: P1 | F13: Must | G13: Relevant content | H13: F11 | I13: =COUNTIF(Tasks!$C$2:$C$86,A13) | J13: =SUMIF(Tasks!$C$2:$C$86,A13,Tasks!$H$2:$H$86) | K13: =COUNTIFS(Tasks!$C$2:$C$86,A13,Tasks!$J$2:$J$86,"Done")
A14: F14 | B14: Bowls | C14: User-created bowls | D14: Trusted users can create bowls and become bowl mods | E14: P5 | F14: Should | G14: Community ownership | H14: F52 | I14: =COUNTIF(Tasks!$C$2:$C$86,A14) | J14: =SUMIF(Tasks!$C$2:$C$86,A14,Tasks!$H$2:$H$86) | K14: =COUNTIFS(Tasks!$C$2:$C$86,A14,Tasks!$J$2:$J$86,"Done")
... A19: F23 | B19: Chat | C19: Realtime messaging | D19: WebSocket gateway, Redis fan-out, typing, receipts, offline sync, optimistic sends | E19: P2 | F19: Must | G19: Feels instant | H19: F01 | I19: =COUNTIF(Tasks!$C$2:$C$86,A19) | J19: =SUMIF(Tasks!$C$2:$C$86,A19,Tasks!$H$2:$H$86) | K19: =COUNTIFS(Tasks!$C$2:$C$86,A19,Tasks!$J$2:$J$86,"Done")
A20: F24 | B20: Chat | C20: PII masking | D20: Regex + rules masker on all UGC before persist; async LLM second pass; encrypted raw vault with 90-day TTL | E20: P1 | F20: Must | G20: Identity stays hidden | I20: =COUNTIF(Tasks!$C$2:$C$86,A20) | J20: =SUMIF(Tasks!$C$2:$C$86,A20,Tasks!$H$2:$H$86) | K20: =COUNTIFS(Tasks!$C$2:$C$86,A20,Tasks!$J$2:$J$86,"Done")
A21: F25 | B21: Chat | C21: Images in chat | D21: Image messages, blurred until tapped, NSFW scan, EXIF strip | E21: P5 | F21: Could | G21: Richer chat | H21: F23 | I21: =COUNTIF(Tasks!$C$2:$C$86,A21) | J21: =SUMIF(Tasks!$C$2:$C$86,A21,Tasks!$H$2:$H$86) | K21: =COUNTIFS(Tasks!$C$2:$C$86,A21,Tasks!$J$2:$J$86,"Done")
A22: F26 | B22: Chat | C22: Disappearing messages | D22: Per-conversation TTL (24h / 7d) | E22: P5 | F22: Could | G22: Less digital footprint | H22: F23 | I22: =COUNTIF(Tasks!$C$2:$C$86,A22) | J22: =SUMIF(Tasks!$C$2:$C$86,A22,Tasks!$H$2:$H$86) | K22: =COUNTIFS(Tasks!$C$2:$C$86,A22,Tasks!$J$2:$J$86,"Done")
A23: F30 | B23: Vent Studio | C23: Host profiles & application | D23: Users apply to host; T&S approves; host badge | E23: P4 | F23: Must | G23: Quality hosts | H23: F52 | I23: =COUNTIF(Tasks!$C$2:$C$86,A23) | J23: =SUMIF(Tasks!$C$2:$C$86,A23,Tasks!$H$2:$H$86) | K23: =COUNTIFS(Tasks!$C$2:$C$86,A23,Tasks!$J$2:$J$86,"Done")
A24: F31 | B24: Vent Studio | C24: Shows & schedule | D24: Recurring shows with episodes, follow a show, reminders | E24: P4 | F24: Must | G24: Appointment listening | H24: F30 | I24: =COUNTIF(Tasks!$C$2:$C$86,A24) | J24: =SUMIF(Tasks!$C$2:$C$86,A24,Tasks!$H$2:$H$86) | K24: =COUNTIFS(Tasks!$C$2:$C$86,A24,Tasks!$J$2:$J$86,"Done")
A25: F32 | B25: Vent Studio | C25: Live audio room | D25: LiveKit room with host, co-host, on-air and listener roles | E25: P4 | F25: Must | G25: RJ-style live show | H25: F31 | I25: =COUNTIF(Tasks!$C$2:$C$86,A25) | J25: =SUMIF(Tasks!$C$2:$C$86,A25,Tasks!$H$2:$H$86) | K25: =COUNTIFS(Tasks!$C$2:$C$86,A25,Tasks!$J$2:$J$86,"Done")
A26: F33 | B26: Vent Studio | C26: Call-in queue | D26: Listener raises hand with an 80-char topic; host brings one caller on air (8 min cap) | E26: P4 | F26: Must | G26: Let it out live | H26: F32 | I26: =COUNTIF(Tasks!$C$2:$C$86,A26) | J26: =SUMIF(Tasks!$C$2:$C$86,A26,Tasks!$H$2:$H$86) | K26: =COUNTIFS(Tasks!$C$2:$C$86,A26,Tasks!$J$2:$J$86,"Done")
A27: F34 | B27: Vent Studio | C27: Voice masking | D27: Optional pitch-shift for callers | E27: P6 | F27: Could | G27: Deeper anonymity | H27: F33 | I27: =COUNTIF(Tasks!$C$2:$C$86,A27) | J27: =SUMIF(Tasks!$C$2:$C$86,A27,Tasks!$H$2:$H$86) | K27: =COUNTIFS(Tasks!$C$2:$C$86,A27,Tasks!$J$2:$J$86,"Done")
A28: F35 | B28: Vent Studio | C28: Reactions & text questions | D28: Emoji reactions and anonymous text questions to the host | E28: P4 | F28: Should | G28: Participate without speaking | H28: F32 | I28: =COUNTIF(Tasks!$C$2:$C$86,A28) | J28: =SUMIF(Tasks!$C$2:$C$86,A28,Tasks!$H$2:$H$86) | K28: =COUNTIFS(Tasks!$C$2:$C$86,A28,Tasks!$J$2:$J$86,"Done")
A29: F36 | B29: Vent Studio | C29: On-air safety controls | D29: Host drop/mute caller, auto-mute on report spike, no recording | E29: P4 | F29: Must | G29: Safe live space | H29: F32,F50 | I29: =COUNTIF(Tasks!$C$2:$C$86,A29) | J29: =SUMIF(Tasks!$C$2:$C$86,A29,Tasks!$H$2:$H$86) | K29: =COUNTIFS(Tasks!$C$2:$C$86,A29,Tasks!$J$2:$J$86,"Done")
A30: F40 | B30: Travel Buddy | C30: Commute plans | D30: Recurring plan: from/to station, departure window, weekdays | E30: P3 | F30: Must | G30: Set once, match daily | H30: F04 | I30: =COUNTIF(Tasks!$C$2:$C$86,A30) | J30: =SUMIF(Tasks!$C$2:$C$86,A30,Tasks!$H$2:$H$86) | K30: =COUNTIFS(Tasks!$C$2:$C$86,A30,Tasks!$J$2:$J$86,"Done")
A31: F41 | B31: Travel Buddy | C31: Travel Now | D31: Live intent: 'leaving Rajiv Chowk -> HUDA City Centre in 10 min'; expires in 45 min | E31: P3 | F31: Must | G31: Spontaneous buddy | H31: F04 | I31: =COUNTIF(Tasks!$C$2:$C$86,A31) | J31: =SUMIF(Tasks!$C$2:$C$86,A31,Tasks!$H$2:$H$86) | K31: =COUNTIFS(Tasks!$C$2:$C$86,A31,Tasks!$J$2:$J$86,"Done")
A32: F42 | B32: Travel Buddy | C32: Vibe match engine | D32: Route overlap (station graph BFS) + time fit + vibe Jaccard + trust; hard filters | E32: P3 | F32: Must | G32: Right person, right train | H32: F40,F41,F03 | I32: =COUNTIF(Tasks!$C$2:$C$86,A32) | J32: =SUMIF(Tasks!$C$2:$C$86,A32,Tasks!$H$2:$H$86) | K32: =COUNTIFS(Tasks!$C$2:$C$86,A32,Tasks!$J$2:$J$86,"Done")
... A41: F53 | B41: Safety | C41: SOS & share trip | D41: Trusted contacts get an SMS with station-level trip progress; SOS button on active trips | E41: P3 | F41: Must | G41: Personal safety | H41: F45 | I41: =COUNTIF(Tasks!$C$2:$C$86,A41) | J41: =SUMIF(Tasks!$C$2:$C$86,A41,Tasks!$H$2:$H$86) | K41: =COUNTIFS(Tasks!$C$2:$C$86,A41,Tasks!$J$2:$J$86,"Done")
A42: F54 | B42: Safety | C42: Safety center | D42: Guidelines, helplines (112, Tele-MANAS 14416), how-to-report | E42: P1 | F42: Must | G42: Know what to do | I42: =COUNTIF(Tasks!$C$2:$C$86,A42) | J42: =SUMIF(Tasks!$C$2:$C$86,A42,Tasks!$H$2:$H$86) | K42: =COUNTIFS(Tasks!$C$2:$C$86,A42,Tasks!$J$2:$J$86,"Done")
A43: F55 | B43: Safety | C43: Grievance & appeals | D43: IT Rules grievance officer flow with 24h ack / 15-day resolution, plus appeals | E43: P1 | F43: Must | G43: Legal compliance | H43: F51 | I43: =COUNTIF(Tasks!$C$2:$C$86,A43) | J43: =SUMIF(Tasks!$C$2:$C$86,A43,Tasks!$H$2:$H$86) | K43: =COUNTIFS(Tasks!$C$2:$C$86,A43,Tasks!$J$2:$J$86,"Done")
A44: F56 | B44: Safety | C44: Self-harm signal handling | D44: Detect distress keywords -> show supportive helpline sheet; never punitive | E44: P1 | F44: Must | G44: Care for vulnerable users | H44: F24 | I44: =COUNTIF(Tasks!$C$2:$C$86,A44) | J44: =SUMIF(Tasks!$C$2:$C$86,A44,Tasks!$H$2:$H$86) | K44: =COUNTIFS(Tasks!$C$2:$C$86,A44,Tasks!$J$2:$J$86,"Done")
A45: F60 | B45: Notifications | C45: Push notifications | D45: Expo push with categories and quiet hours | E45: P2 | F45: Must | G45: Don't miss matches/replies | H45: F01 | I45: =COUNTIF(Tasks!$C$2:$C$86,A45) | J45: =SUMIF(Tasks!$C$2:$C$86,A45,Tasks!$H$2:$H$86) | K45: =COUNTIFS(Tasks!$C$2:$C$86,A45,Tasks!$J$2:$J$86,"Done")
A46: F61 | B46: Notifications | C46: In-app inbox | D46: Notification list with read state | E46: P2 | F46: Should | G46: Catch up | H46: F60 | I46: =COUNTIF(Tasks!$C$2:$C$86,A46) | J46: =SUMIF(Tasks!$C$2:$C$86,A46,Tasks!$H$2:$H$86) | K46: =COUNTIFS(Tasks!$C$2:$C$86,A46,Tasks!$J$2:$J$86,"Done")
A47: F70 | B47: Platform | C47: Admin console | D47: React/Vite moderator console under /admin with RBAC | E47: P1 | F47: Must | G47: Operate the platform | H47: F51 | I47: =COUNTIF(Tasks!$C$2:$C$86,A47) | J47: =SUMIF(Tasks!$C$2:$C$86,A47,Tasks!$H$2:$H$86) | K47: =COUNTIFS(Tasks!$C$2:$C$86,A47,Tasks!$J$2:$J$86,"Done")
A48: F71 | B48: Platform | C48: Analytics | D48: PII-free product events (signup funnel, D1/D7, matches, sessions) | E48: P2 | F48: Should | G48: Learn what works | I48: =COUNTIF(Tasks!$C$2:$C$86,A48) | J48: =SUMIF(Tasks!$C$2:$C$86,A48,Tasks!$H$2:$H$86) | K48: =COUNTIFS(Tasks!$C$2:$C$86,A48,Tasks!$J$2:$J$86,"Done")
A49: F72 | B49: Platform | C49: Data export & deletion | D49: DPDP rights: export JSON, delete account within 30 days | E49: P1 | F49: Must | G49: User rights | H49: F01 | I49: =COUNTIF(Tasks!$C$2:$C$86,A49) | J49: =SUMIF(Tasks!$C$2:$C$86,A49,Tasks!$H$2:$H$86) | K49: =COUNTIFS(Tasks!$C$2:$C$86,A49,Tasks!$J$2:$J$86,"Done")
A50: F73 | B50: Platform | C50: Public site | D50: Landing, privacy, terms, grievance officer, community guidelines (Go templates) | E50: P1 | F50: Must | G50: Store listing requirements | I50: =COUNTIF(Tasks!$C$2:$C$86,A50) | J50: =SUMIF(Tasks!$C$2:$C$86,A50,Tasks!$H$2:$H$86) | K50: =COUNTIFS(Tasks!$C$2:$C$86,A50,Tasks!$J$2:$J$86,"Done")
A51: F74 | B51: Platform | C51: Hindi i18n | D51: Hindi + English UI, Hinglish-tolerant masker | E51: P5 | F51: Should | G51: Reach more commuters | I51: =COUNTIF(Tasks!$C$2:$C$86,A51) | J51: =SUMIF(Tasks!$C$2:$C$86,A51,Tasks!$H$2:$H$86) | K51: =COUNTIFS(Tasks!$C$2:$C$86,A51,Tasks!$J$2:$J$86,"Done")
A52: F80 | B52: AI | C52: AI moderation assist | D52: Haiku triage of reports/UGC -> severity + reason; human decides | E52: P5 | F52: Should | G52: Faster moderation | H52: F51 | I52: =COUNTIF(Tasks!$C$2:$C$86,A52) | J52: =SUMIF(Tasks!$C$2:$C$86,A52,Tasks!$H$2:$H$86) | K52: =COUNTIFS(Tasks!$C$2:$C$86,A52,Tasks!$J$2:$J$86,"Done")
...

Sheet Tasks
A1: Task ID | B1: Phase | C1: Feature ID | D1: Layer | E1: Task | F1: Acceptance criteria | G1: Priority | H1: Est (days) | I1: Depends on | J1: Status | K1: Owner
A2: T001 | B2: P0 | D2: Infra | E2: Monorepo: apps/mobile (Expo+TS+Router+NativeWind), server (Go+Echo), admin (Vite) | F2: All three build locally with one command each | G2: Must | H2: 1 | J2: Todo
A3: T002 | B3: P0 | D3: Infra | E3: Railway: API service, Postgres, Redis; env var schema | F3: Health endpoint live on Railway with DB and Redis ping | G3: Must | H3: 1 | I3: T001 | J3: Todo
A4: T003 | B4: P0 | D4: Infra | E4: CI: go test, go vet, tsc, eslint, npm audit, govulncheck | F4: PR fails on test/type/high-vuln errors | G4: Must | H4: 1 | I4: T001 | J4: Todo
A5: T004 | B5: P0 | D5: Infra | E5: EAS Build + EAS Update channels (dev/preview/prod) | F5: Preview build installs on Android and iOS TestFlight | G5: Must | H5: 1 | I5: T001 | J5: Todo
A6: T005 | B6: P0 | D6: Backend | E6: DB layer: GORM, UUIDv7 base model, cursor pagination helper, migrations folder | F6: Paginated list helper unit-tested | G6: Must | H6: 1 | I6: T002 | J6: Todo
A7: T006 | B7: P0 | D7: Backend | E7: Error envelope, request ID, structured logging with denylist, panic recovery | F7: No stack traces or PII in responses or logs | G7: Must | H7: 1 | I7: T005 | J7: Todo
A8: T007 | B8: P0 | D8: Backend | E8: Redis rate limiter middleware (sliding window, keyed by ip/user/trust tier) | F8: 429 returned past limit; limits configurable per route | G8: Must | H8: 1 | I8: T002 | J8: Todo
A9: T010 | B9: P0 | C9: F01 | D9: Backend | E9: OTP request/verify with MSG91, HMAC phone hash, encrypted phone, throttling | F9: 5 attempts max, 5 min TTL, per-number and per-IP throttles | G9: Must | H9: 2 | I9: T007 | J9: Todo
A10: T011 | B10: P0 | C10: F01 | D10: Backend | E10: JWT access + rotating refresh tokens with family reuse detection | F10: Reused refresh token revokes the family | G10: Must | H10: 2 | I10: T010 | J10: Todo
A11: T012 | B11: P0 | C11: F01 | D11: Mobile | E11: Auth screens: phone entry, OTP entry, secure-store token handling, auto refresh | F11: Cold start restores session; logout clears secure store | G11: Must | H11: 2 | I11: T011 | J11: Todo
A12: T013 | B12: P0 | C12: F05 | D12: Mobile | E12: Age gate + itemised consent screen; consent records API | F12: Cannot proceed without 18+ and core consent | G12: Must | H12: 1 | I12: T012 | J12: Todo
A13: T014 | B13: P0 | C13: F02 | D13: Backend | E13: Persona service: alias generator, avatar seed, re-roll, alias history, 30-day change rule | F13: Aliases unique per city; history kept | G13: Must | H13: 1 | I13: T011 | J13: Todo
A14: T015 | B14: P0 | C14: F02 | D14: Mobile | E14: Persona creation screen with re-roll and generated avatar component | F14: Avatar renders deterministically from seed | G14: Must | H14: 1 | I14: T014 | J14: Todo
A15: T016 | B15: P0 | D15: Backend | E15: Metro seed: cities, lines, stations, line_stations, interchange edges from GTFS (Delhi NCR first) | F15: BFS returns correct path Rajiv Chowk -> HUDA City Centre | G15: Must | H15: 3 | I15: T005 | J15: Todo
A16: T017 | B16: P0 | C16: F04 | D16: Mobile | E16: Station picker (search, line colour chips) + home metro setup screen | F16: Search by name in under 100ms on device | G16: Must | H16: 1 | I16: T016 | J16: Todo
A17: T018 | B17: P0 | C17: F03 | D17: Backend | E17: Vibe tag catalog + persona vibes + intents API | F17: 3-10 tags enforced | G17: Must | H17: 1 | I17: T014 | J17: Todo
A18: T019 | B18: P0 | C18: F03 | D18: Mobile | E18: Vibe picker screen | F18: Selections saved and editable from profile | G18: Must | H18: 1 | I18: T018 | J18: Todo
A19: T020 | B19: P0 | C19: F50 | D19: Backend | E19: Blocks, mutes, reports tables and APIs; excludeBlocked scope helper | F19: Blocked personas invisible both ways in every list endpoint | G19: Must | H19: 2 | I19: T014 | J19: Todo
A20: T021 | B20: P0 | C20: F50 | D20: Mobile | E20: Reusable report/block/mute action sheet | F20: Reachable from profile, post, comment, message | G20: Must | H20: 1 | I20: T020 | J20: Todo
A21: T022 | B21: P0 | D21: Mobile | E21: App shell: tabs (Bowls, Chats, Travel, Studio, Me), theme, typed API client, TanStack Query setup | F21: Tabs navigate; API errors show toast | G21: Must | H21: 1 | I21: T012 | J21: Todo
A22: T030 | B22: P1 | C22: F24 | D22: Backend | E22: PII masker package: Indian phone, email, UPI, Aadhaar (Verhoeff), PAN, handles, URLs; table-driven tests | F22: >=95% recall on test corpus incl. spaced/dashed numbers | G22: Must | H22: 3 | I22: T005 | J22: Todo
A23: T031 | B23: P1 | C23: F24 | D23: Backend | E23: PII vault: AES-GCM encrypted raw text, 90-day TTL purge job, audited access | F23: Purge job deletes expired rows; access writes audit log | G23: Must | H23: 1 | I23: T030 | J23: Todo
A24: T032 | B24: P1 | C24: F24 | D24: Backend | E24: Async LLM second pass (Haiku) for obfuscated PII; emits update event | F24: Spelled-out number gets masked and clients update | G24: Should | H24: 2 | I24: T030 | J24: Todo
A25: T033 | B25: P1 | C25: F10 | D25: Backend | E25: Bowls: CRUD (admin), membership, suggestions by line/station/hub/college | F25: New user sees line + station + city bowls suggested | G25: Must | H25: 2 | I25: T016 | J25: Todo
A26: T034 | B26: P1 | C26: F11 | D26: Backend | E26: Posts API: text/image/poll, flair, masked body, R2 pre-signed upload, EXIF strip | F26: Post body never stored unmasked | G26: Must | H26: 3 | I26: T030,T033 | J26: Todo
A27: T035 | B27: P1 | C27: F12 | D27: Backend | E27: Comments (2 levels) + votes with denormalised counters | F27: Vote idempotent per persona | G27: Must | H27: 2 | I27: T034 | J27: Todo
A28: T036 | B28: P1 | C28: F13 | D28: Backend | E28: Feed endpoints Hot/New/Top; hot score cron every 5 min; cursor pagination | F28: p95 feed latency < 200ms on 100k posts | G28: Must | H28: 2 | I28: T035 | J28: Todo
A29: T037 | B29: P1 | C29: F10 | D29: Mobile | E29: Bowls tab: discover, joined list, bowl screen | F29: Join/leave reflects immediately | G29: Must | H29: 2 | I29: T033 | J29: Todo
A30: T038 | B30: P1 | C30: F11 | D30: Mobile | E30: Composer: text, image, poll, flair; PII preview warning | F30: User sees masked preview before posting | G30: Must | H30: 2 | I30: T034 | J30: Todo
A31: T039 | B31: P1 | C31: F12 | D31: Mobile | E31: Post detail with threaded comments, votes, OP badge | F31: FlashList renders 500 comments smoothly | G31: Must | H31: 2 | I31: T035 | J31: Todo
A32: T040 | B32: P1 | C32: F15 | D32: Backend | E32: Daily prompt scheduler per city + pinned prompt post | F32: One prompt per city per day | G32: Should | H32: 1 | I32: T034 | J32: Todo
A33: T041 | B33: P1 | C33: F70 | D33: Admin | E33: Admin console shell, RBAC (moderator, ts_lead, admin), login | F33: Moderators cannot access vault | G33: Must | H33: 2 | I33: T011 | J33: Todo
... A63: T080 | B63: P3 | C63: F45 | D63: Mobile | E63: Trip screen: meet point, check-in, share trip, SOS, feedback | F63: SOS reachable in 1 tap on active trip | G63: Must | H63: 2 | I63: T075,T077 | J63: Todo
A64: T081 | B64: P3 | D64: Infra | E64: Launch checklist: store listings, privacy labels, UGC compliance, load test | F64: Both stores approve | G64: Must | H64: 3 | I64: T080 | J64: Todo
A65: T090 | B65: P4 | C65: F30 | D65: Backend | E65: Host applications + host profile + approval in admin | F65: Only approved hosts create shows | G65: Must | H65: 1 | I65: T042 | J65: Todo
A66: T091 | B66: P4 | C66: F31 | D66: Backend | E66: Shows, episodes, follows, reminders | F66: Followers get push 10 min before episode | G66: Must | H66: 2 | I66: T090,T060 | J66: Todo
A67: T092 | B67: P4 | C67: F32 | D67: Backend | E67: LiveKit integration: room per episode, role-based tokens, webhooks | F67: Listener token cannot publish audio | G67: Must | H67: 3 | I67: T091 | J67: Todo
A68: T093 | B68: P4 | C68: F33 | D68: Backend | E68: Call-in queue, stage/unstage, 8-min cap, token revoke on drop | F68: Dropped caller loses publish within 2s | G68: Must | H68: 2 | I68: T092 | J68: Todo
A69: T094 | B69: P4 | C69: F35 | D69: Backend | E69: Reactions + text questions (masked) over WS | F69: Questions pass PII masker | G69: Should | H69: 1 | I69: T092,T030 | J69: Todo
...

Sheet Phase Summary
A1: Phase | B1: Name | C1: Tasks | D1: Est (days) | E1: Done | F1: % done
A2: P0 | B2: Foundation | C2: =COUNTIF(Tasks!$B$2:$B$86,A2) | D2: =SUMIF(Tasks!$B$2:$B$86,A2,Tasks!$H$2:$H$86) | E2: =COUNTIFS(Tasks!$B$2:$B$86,A2,Tasks!$J$2:$J$86,"Done") | F2: =IF(C2=0,0,E2/C2)
A3: P1 | B3: Bowls | C3: =COUNTIF(Tasks!$B$2:$B$86,A3) | D3: =SUMIF(Tasks!$B$2:$B$86,A3,Tasks!$H$2:$H$86) | E3: =COUNTIFS(Tasks!$B$2:$B$86,A3,Tasks!$J$2:$J$86,"Done") | F3: =IF(C3=0,0,E3/C3)
A4: P2 | B4: Chat & discussion | C4: =COUNTIF(Tasks!$B$2:$B$86,A4) | D4: =SUMIF(Tasks!$B$2:$B$86,A4,Tasks!$H$2:$H$86) | E4: =COUNTIFS(Tasks!$B$2:$B$86,A4,Tasks!$J$2:$J$86,"Done") | F4: =IF(C4=0,0,E4/C4)
A5: P3 | B5: Travel Buddy (MVP launch) | C5: =COUNTIF(Tasks!$B$2:$B$86,A5) | D5: =SUMIF(Tasks!$B$2:$B$86,A5,Tasks!$H$2:$H$86) | E5: =COUNTIFS(Tasks!$B$2:$B$86,A5,Tasks!$J$2:$J$86,"Done") | F5: =IF(C5=0,0,E5/C5)
A6: P4 | B6: Vent Studio | C6: =COUNTIF(Tasks!$B$2:$B$86,A6) | D6: =SUMIF(Tasks!$B$2:$B$86,A6,Tasks!$H$2:$H$86) | E6: =COUNTIFS(Tasks!$B$2:$B$86,A6,Tasks!$J$2:$J$86,"Done") | F6: =IF(C6=0,0,E6/C6)
A7: P5 | B7: Trust & growth | C7: =COUNTIF(Tasks!$B$2:$B$86,A7) | D7: =SUMIF(Tasks!$B$2:$B$86,A7,Tasks!$H$2:$H$86) | E7: =COUNTIFS(Tasks!$B$2:$B$86,A7,Tasks!$J$2:$J$86,"Done") | F7: =IF(C7=0,0,E7/C7)
A8: P6 | B8: Later | C8: =COUNTIF(Tasks!$B$2:$B$86,A8) | D8: =SUMIF(Tasks!$B$2:$B$86,A8,Tasks!$H$2:$H$86) | E8: =COUNTIFS(Tasks!$B$2:$B$86,A8,Tasks!$J$2:$J$86,"Done") | F8: =IF(C8=0,0,E8/C8)
A9: Total | C9: =SUM(C2:C8) | D9: =SUM(D2:D8) | E9: =SUM(E2:E8) | F9: =IF(C9=0,0,E9/C9)

Sheet Entities
A1: Entity | B1: Domain | C1: Description | D1: Retention | E1: Field count
A2: User | B2: Identity | C2: Private account. Never exposed to other users. | D2: Until deletion + 30 days | E2: 15
A3: Persona | B3: Identity | C3: Public anonymous face. All social objects point here. | D3: Tombstoned on user deletion | E3: 13
A4: PersonaAliasHistory | B4: Identity | C4: Old aliases for moderation lookups. | D4: Life of account | E4: 5
A5: Device | B5: Identity | C5: Install with push token. | D5: 90 days after last seen | E5: 9
A6: RefreshToken | B6: Identity | C6: Rotating refresh tokens (hashed). | D6: Expiry + 7 days | E6: 8
A7: Consent | B7: Identity | C7: DPDP itemised consent records (append-only). | D7: Life of account + 3 years | E7: 6
A8: TrustedContact | B8: Identity | C8: SOS / share-trip recipients. | D8: Until removed | E8: 6
A9: UserSettings | B9: Identity | C9: Per-user preferences. | D9: Life of account | E9: 9
A10: City | B10: Metro | C10: Metro city. | D10: Reference | E10: 4
A11: MetroLine | B11: Metro | C11: Line within a city. | D11: Reference | E11: 5
A12: Station | B12: Metro | C12: Metro station. | D12: Reference | E12: 8
A13: LineStation | B13: Metro | C13: Ordered station on a line (graph edges = consecutive seq). | D13: Reference | E13: 4
... A57: AiUsage | B57: System | C57: Per-call AI cost tracking. | D57: 2 years | E57: 8

Sheet Fields
A1: Entity | B1: Domain | C1: Field | D1: Type | E1: Constraints | F1: Privacy class | G1: Note
A2: User | B2: Identity | C2: id | D2: uuid v7 | E2: PK | F2: P0
A3: User | B3: Identity | C3: created_at | D3: timestamptz | E3: not null | F3: P0
A4: User | B4: Identity | C4: updated_at | D4: timestamptz | E4: not null | F4: P0
A5: User | B5: Identity | C5: deleted_at | D5: timestamptz | E5: nullable, index | F5: P0 | G5: soft delete
A6: User | B6: Identity | C6: phone_hash | D6: bytea | E6: unique, not null | F6: P3 | G6: HMAC-SHA256(pepper, E.164)
A7: User | B7: Identity | C7: phone_enc | D7: bytea | E7: not null | F7: P3 | G7: AES-GCM; used only for SMS
A8: User | B8: Identity | C8: status | D8: enum user_status | E8: not null, index | F8: P0
A9: User | B9: Identity | C9: birth_year | D9: smallint | E9: not null | F9: P2 | G9: 18+ check; age band derived
A10: User | B10: Identity | C10: gender | D10: enum gender | E10: nullable | F10: P2 | G10: self-declared; for matching filters only
A11: User | B11: Identity | C11: city_id | D11: uuid | E11: FK City | F11: P2
A12: User | B12: Identity | C12: verified_at | D12: timestamptz | E12: nullable | F12: P2 | G12: selfie liveness passed
A13: User | B13: Identity | C13: trust_score | D13: int | E13: default 50 | F13: P2 | G13: 0-100
A14: User | B14: Identity | C14: trust_tier | D14: smallint | E14: default 0, index | F14: P2 | G14: derived from score
A15: User | B15: Identity | C15: locale | D15: varchar(8) | E15: default 'en' | F15: P2
A16: User | B16: Identity | C16: last_active_at | D16: timestamptz | E16: index | F16: P2
A17: Persona | B17: Identity | C17: id | D17: uuid v7 | E17: PK | F17: P0
A18: Persona | B18: Identity | C18: created_at | D18: timestamptz | E18: not null | F18: P0
A19: Persona | B19: Identity | C19: updated_at | D19: timestamptz | E19: not null | F19: P0
A20: Persona | B20: Identity | C20: deleted_at | D20: timestamptz | E20: nullable, index | F20: P0 | G20: soft delete
A21: Persona | B21: Identity | C21: user_id | D21: uuid | E21: FK User, unique | F21: P3 | G21: never serialized to other clients
A22: Persona | B22: Identity | C22: alias | D22: varchar(40) | E22: unique per city | F22: P1
A23: Persona | B23: Identity | C23: avatar_seed | D23: varchar(32) | E23: not null | F23: P1
A24: Persona | B24: Identity | C24: bio | D24: varchar(160) | E24: masked | F24: P1
A25: Persona | B25: Identity | C25: alias_changed_at | D25: timestamptz | E25: nullable | F25: P0 | G25: 30-day rule
A26: Persona | B26: Identity | C26: home_station_id | D26: uuid | E26: FK Station | F26: P2 | G26: never shown to others
A27: Persona | B27: Identity | C27: work_station_id | D27: uuid | E27: FK Station | F27: P2 | G27: never shown to others
A28: Persona | B28: Identity | C28: intents | D28: text[] | E28: enum persona_intent values | F28: P1
A29: Persona | B29: Identity | C29: is_host | D29: bool | E29: default false | F29: P1
A30: PersonaAliasHistory | B30: Identity | C30: id | D30: uuid v7 | E30: PK | F30: P0
A31: PersonaAliasHistory | B31: Identity | C31: persona_id | D31: uuid | E31: FK Persona, index | F31: P1
A32: PersonaAliasHistory | B32: Identity | C32: alias | D32: varchar(40) | F32: P1
A33: PersonaAliasHistory | B33: Identity | C33: used_from | D33: timestamptz | F33: P0
A34: PersonaAliasHistory | B34: Identity | C34: used_to | D34: timestamptz | F34: P0
A35: Device | B35: Identity | C35: id | D35: uuid v7 | E35: PK | F35: P0
A36: Device | B36: Identity | C36: created_at | D36: timestamptz | E36: not null | F36: P0
A37: Device | B37: Identity | C37: updated_at | D37: timestamptz | E37: not null | F37: P0
A38: Device | B38: Identity | C38: user_id | D38: uuid | E38: FK User, index | F38: P3
A39: Device | B39: Identity | C39: platform | D39: enum platform | F39: P0
A40: Device | B40: Identity | C40: push_token | D40: text | E40: nullable | F40: P2
...

Sheet Enums
A1: Enum | B1: Values
A2: user_status | B2: active, suspended, banned, pending_deletion, deleted
A3: gender | B3: woman, man, non_binary, prefer_not_to_say
A4: platform | B4: ios, android
A5: consent_purpose | B5: core_service, travel_matching, ai_processing, analytics, marketing_push
A6: dm_policy | B6: requests, nobody
A7: persona_intent | B7: vent, listen, travel_buddy, friends, discuss
A8: vibe_category | B8: talk_style, music, sport, hobby, work, study, food, wellbeing
A9: bowl_kind | B9: city, line, station, office_hub, college, topic
A10: bowl_visibility | B10: public, members_only
A11: bowl_role | B11: member, moderator, owner
A12: post_type | B12: text, image, poll
... A46: ai_purpose | B46: pii_second_pass, moderation_triage, icebreaker, host_topics
